Workbook

Sheet MACC
A1: ПРЕДПОСЫЛКИ
A2: Ставка дисконтирования | C2: 0.12 | D2: Гибридная ставка для КЗ
A3: Общие выбросы | C3: =Выбросы!C33 -> 353 | D3: Mt CO₂eq, UNFCCC NIR 2023 (2021)
A5: Сектор | B5: # пп | C5: № | D5: Мероприятие | E5: CAPEX mUSD | F5: OPEX mUSD/год | G5: Срок лет | H5: Снижение kt CO₂eq/год | I5: NPV mUSD | J5: Диск. CO₂ kt | K5: MAC USD/t
A6: 3 | B6: 22 | C6: 5 | D6: Точное земледелие (снижение N₂O от удобрений) | E6: =Расчёты!C670 -> 180 | F6: =Расчёты!C671 -> -66 | G6: =Расчёты!C672 -> 10 | H6: =Расчёты!C673 -> 4280 | I6: =E6-PV($C$2,G6,F6) -> -192.91472 | J6: =-PV($C$2,G6,H6) -> 24182.955 | K6: =IF(J6=0,0,I6/J6*1000) -> -7.9773015
A7: 3 | B7: 23 | C7: 6 | D7: Улучшение управления пастбищами | E7: =Расчёты!C694 -> 230 | F7: =Расчёты!C695 -> -45.4 | G7: =Расчёты!C696 -> 20 | H7: =Расчёты!C697 -> 2140 | I7: =E7-PV($C$2,G7,F7) -> -109.11274 | J7: =-PV($C$2,G7,H7) -> 15984.609 | K7: =IF(J7=0,0,I7/J7*1000) -> -6.8261124
A8: 1.B | B8: 15 | C8: 2 | D8: Утилизация попутного нефтяного газа (ПНГ) | E8: =Расчёты!C494 -> 1875 | F8: =Расчёты!C495 -> -277.08333 | G8: =Расчёты!C496 -> 20 | H8: =Расчёты!C497 -> 6840 | I8: =E8-PV($C$2,G8,F8) -> -194.65834 | J8: =-PV($C$2,G8,H8) -> 51090.994 | K8: =IF(J8=0,0,I8/J8*1000) -> -3.8100323
A9: 1.A.1 | B9: 8 | C9: 8 | D9: ВИЭ + газовый пикер + котельная (альтернатива новым ТЭЦ) | E9: =Расчёты!C130 -> -695.71429 | F9: =Расчёты!C131 -> 76.667581 | G9: =Расчёты!C132 -> 25 | H9: =Расчёты!C133 -> 4029.6 | I9: =E9-PV($C$2,G9,F9) -> -94.399781 | J9: =-PV($C$2,G9,H9) -> 31604.713 | K9: =IF(J9=0,0,I9/J9*1000) -> -2.9868893
A10: 1.B | B10: 14 | C10: 1 | D10: LDAR: обнаружение и устранение утечек метана (нефтегаз) | E10: =Расчёты!C469 -> 55 | F10: =Расчёты!C470 -> 2.5 | G10: =Расчёты!C471 -> 10 | H10: =Расчёты!C472 -> 8550 | I10: =E10-PV($C$2,G10,F10) -> 69.125558 | J10: =-PV($C$2,G10,H10) -> 48309.407 | K10: =IF(J10=0,0,I10/J10*1000) -> 1.4308923
A11: 3 | B11: 21 | C11: 4 | D11: Улучшение управления навозом (биогаз) | E11: =Расчёты!C646 -> 300 | F11: =Расчёты!C647 -> -13 | G11: =Расчёты!C648 -> 15 | H11: =Расчёты!C649 -> 3424 | I11: =E11-PV($C$2,G11,F11) -> 211.45876 | J11: =-PV($C$2,G11,H11) -> 23320.4 | K11: =IF(J11=0,0,I11/J11*1000) -> 9.0675444
A12: 5 | B12: 26 | C12: 1 | D12: Модернизация очистных сооружений (снижение CH₄) | E12: =Расчёты!C745 -> 150 | F12: =Расчёты!C746 -> -10.5 | G12: =Расчёты!C747 -> 25 | H12: =Расчёты!C748 -> 320 | I12: =E12-PV($C$2,G12,F12) -> 67.647039 | J12: =-PV($C$2,G12,H12) -> 2509.8045 | K12: =IF(J12=0,0,I12/J12*1000) -> 26.953111
A13: 1.A.4 | B13: 11 | C13: 1 | D13: Термомодернизация зданий (утепление фасадов, окна, кровля) | E13: =Расчёты!C373 -> 10800 | F13: =Расчёты!C374 -> -769.26724 | G13: =Расчёты!C375 -> 30 | H13: =Расчёты!C376 -> 9217.2414 | I13: =E13-PV($C$2,G13,F13) -> 4603.4109 | J13: =-PV($C$2,G13,H13) -> 74246.575 | K13: =IF(J13=0,0,I13/J13*1000) -> 62.001659
A14: 1.B | B14: 16 | C14: 3 | D14: Дегазация угольных шахт (метан угольных пластов) | E14: =Расчёты!C518 -> 300 | F14: =Расчёты!C519 -> 10.531231 | G14: =Расчёты!C520 -> 20 | H14: =Расчёты!C521 -> 1900 | I14: =E14-PV($C$2,G14,F14) -> 378.66243 | J14: =-PV($C$2,G14,H14) -> 14191.943 | K14: =IF(J14=0,0,I14/J14*1000) -> 26.681508
A15: 1.A.1 | B15: 3 | C15: 3 | D15: ВИЭ: солнечные и ветровые станции | E15: =Расчёты!C85 -> 9200 | F15: =Расчёты!C86 -> -144.21136 | G15: =Расчёты!C87 -> 25 | H15: =Расчёты!C88 -> 27594 | I15: =E15-PV($C$2,G15,F15) -> 8068.9302 | J15: =-PV($C$2,G15,H15) -> 216423.58 | K15: =IF(J15=0,0,I15/J15*1000) -> 37.283046
A16: 1.A.1 | B16: 6 | C16: 6 | D16: Тепловые насосы для централизованного теплоснабжения | E16: =Расчёты!C240 -> 1352.6845 | F16: =Расчёты!C241 -> 24.691179 | G16: =Расчёты!C242 -> 20 | H16: =Расчёты!C243 -> 5225 | I16: =E16-PV($C$2,G16,F16) -> 1537.1139 | J16: =-PV($C$2,G16,H16) -> 39027.843 | K16: =IF(J16=0,0,I16/J16*1000) -> 39.385058
A17: 5 | B17: 25 | C17: 2 | D17: Улавливание и утилизация свалочного газа (LFG) | E17: =Расчёты!C722 -> 140 | F17: =Расчёты!C723 -> -4.4114286 | G17: =Расчёты!C724 -> 20 | H17: =Расчёты!C725 -> 360 | I17: =E17-PV($C$2,G17,F17) -> 107.04908 | J17: =-PV($C$2,G17,H17) -> 2688.9997 | K17: =IF(J17=0,0,I17/J17*1000) -> 39.810002
A18: 3 | B18: 20 | C18: 3 | D18: Кормовые добавки для снижения энтеральной ферментации (CH₄) | E18: =Расчёты!C622 -> 140.25 | F18: =Расчёты!C623 -> 153 | G18: =Расчёты!C624 -> 10 | H18: =Расчёты!C625 -> 1780 | I18: =E18-PV($C$2,G18,F18) -> 1004.7341 | J18: =-PV($C$2,G18,H18) -> 10057.397 | K18: =IF(J18=0,0,I18/J18*1000) -> 99.900016
A19: 1.A.2 | B19: 9 | C19: 1 | D19: Утилизация ВЭР (рекуперация тепла отходящих газов) | E19: =Расчёты!C302 -> 6250 | F19: =Расчёты!C303 -> 8.3181818 | G19: =Расчёты!C304 -> 20 | H19: =Расчёты!C305 -> 17520 | I19: =E19-PV($C$2,G19,F19) -> 6312.1322 | J19: =-PV($C$2,G19,H19) -> 130864.65 | K19: =IF(J19=0,0,I19/J19*1000) -> 48.23405
A20: 2 | B20: 18 | C20: 1 | D20: Снижение клинкерного фактора в цементном производстве | E20: =Расчёты!C569 -> 200 | F20: =Расчёты!C570 -> 20 | G20: =Расчёты!C571 -> 30 | H20: =Расчёты!C572 -> 860 | I20: =E20-PV($C$2,G20,F20) -> 361.10368 | J20: =-PV($C$2,G20,H20) -> 6927.4582 | K20: =IF(J20=0,0,I20/J20*1000) -> 52.126432
A21: 1.A.1 | B21: 4 | C21: 4 | D21: ВИЭ + газовый пикер + котельная на месте ТЭЦ (закрытие старых угольных ТЭЦ) | E21: =Расчёты!C172 -> 5880 | F21: =Расчёты!C173 -> 781.22801 | G21: =Расчёты!C174 -> 25 | H21: =Расчёты!C175 -> 28207.2 | I21: =E21-PV($C$2,G21,F21) -> 12007.28 | J21: =-PV($C$2,G21,H21) -> 221232.99 | K21: =IF(J21=0,0,I21/J21*1000) -> 54.274364
A22: 1.A.4 | B22: 13 | C22: 3 | D22: Электрокотёл + ВИЭ (полная декарбонизация ЖКХ) | E22: =Расчёты!C443 -> 184.3229 | F22: =Расчёты!C444 -> 1138.2487 | G22: =Расчёты!C445 -> 25 | H22: =Расчёты!C446 -> 11625 | I22: =E22-PV($C$2,G22,F22) -> 9111.7656 | J22: =-PV($C$2,G22,H22) -> 91176.492 | K22: =IF(J22=0,0,I22/J22*1000) -> 99.93547
A23: 1.B | B23: 17 | C23: 4 | D23: Снижение утечек в газотранспортной системе | E23: =Расчёты!C544 -> 630 | F23: =Расчёты!C545 -> 354.68182 | G23: =Расчёты!C546 -> 20 | H23: =Расчёты!C547 -> 5130 | I23: =E23-PV($C$2,G23,F23) -> 3279.2758 | J23: =-PV($C$2,G23,H23) -> 38318.246 | K23: =IF(J23=0,0,I23/J23*1000) -> 85.58001
A24: 1.A.1 | B24: 7 | C24: 7 | D24: Электрификация теплоснабжения (электрокотлы + ВИЭ) | E24: =Расчёты!C277 -> 4767.5034 | F24: =Расчёты!C278 -> 2669.3076 | G24: =Расчёты!C279 -> 25 | H24: =Расчёты!C280 -> 28215 | I24: =E24-PV($C$2,G24,F24) -> 25703.254 | J24: =-PV($C$2,G24,H24) -> 221294.17 | K24: =IF(J24=0,0,I24/J24*1000) -> 116.14971
A25: 2 | B25: 19 | C25: 2 | D25: CCS в металлургии и цементе | E25: =Расчёты!C593 -> 1203.4286 | F25: =Расчёты!C594 -> 185.14286 | G25: =Расчёты!C595 -> 25 | H25: =Расчёты!C596 -> 2160 | I25: =E25-PV($C$2,G25,F25) -> 2655.5298 | J25: =-PV($C$2,G25,H25) -> 16941.18 | K25: =IF(J25=0,0,I25/J25*1000) -> 156.74998
A26: 1.A.4 | B26: 12 | C26: 2 | D26: Газификация ЖКХ (переходная мера) | E26: =Расчёты!C404 -> 2500.6 | F26: =Расчёты!C405 -> 864.588 | G26: =Расчёты!C406 -> 30 | H26: =Расчёты!C407 -> 6975 | I26: =E26-PV($C$2,G26,F26) -> 9465.0154 | J26: =-PV($C$2,G26,H26) -> 56184.908 | K26: =IF(J26=0,0,I26/J26*1000) -> 168.46188
A27: 1.A.1 | B27: 5 | C27: 5 | D27: Атомная энергетика (замещение базовой угольной нагрузки) | E27: =Расчёты!C202 -> 36036 | F27: =Расчёты!C203 -> 261.96382 | G27: =Расчёты!C204 -> 60 | H27: =Расчёты!C205 -> 26805.6 | I27: =E27-PV($C$2,G27,F27) -> 38216.6 | J27: =-PV($C$2,G27,H27) -> 223131.14 | K27: =IF(J27=0,0,I27/J27*1000) -> 171.27417
A28: 4 | B28: 24 | C28: 1 | D28: Лесонасаждение (афорестация и лесовосстановление) | E28: =Расчёты!C773 -> 2200 | F28: =Расчёты!C774 -> 111 | G28: =Расчёты!C775 -> 30 | H28: =Расчёты!C776 -> 2100 | I28: =E28-PV($C$2,G28,F28) -> 3094.1254 | J28: =-PV($C$2,G28,H28) -> 16915.886 | K28: =IF(J28=0,0,I28/J28*1000) -> 182.9124
A29: 1.A.1 | B29: 2 | C29: 2 | D29: Перевод угольных ТЭЦ и котельных на природный газ | E29: =Расчёты!C54 -> 10500 | F29: =Расчёты!C55 -> 928.11446 | G29: =Расчёты!C56 -> 20 | H29: =Расчёты!C57 -> 12045 | I29: =E29-PV($C$2,G29,F29) -> 17432.499 | J29: =-PV($C$2,G29,H29) -> 89969.448 | K29: =IF(J29=0,0,I29/J29*1000) -> 193.7602
A30: 1.A.3 | B30: 10 | C30: 1 | D30: Электрификация легкового транспорта (EV) | E30: =Расчёты!C335 -> 8798.7013 | F30: =Расчёты!C336 -> -642.30519 | G30: =Расчёты!C337 -> 15 | H30: =Расчёты!C338 -> 2184.2776 | I30: =E30-PV($C$2,G30,F30) -> 4424.0477 | J30: =-PV($C$2,G30,H30) -> 14876.819 | K30: =IF(J30=0,0,I30/J30*1000) -> 297.37861
A31: 1.A.1 | B31: 1 | C31: 1 | D31: Повышение КПД угольных ТЭЦ (модернизация турбин и котлов) | E31: =Расчёты!C24 -> 9750 | F31: =Расчёты!C25 -> 69.825 | G31: =Расчёты!C26 -> 20 | H31: =Расчёты!C27 -> 2706 | I31: =E31-PV($C$2,G31,F31) -> 10271.554 | J31: =-PV($C$2,G31,H31) -> 20212.314 | K31: =IF(J31=0,0,I31/J31*1000) -> 508.18297
D32: ИТОГО | E32: =SUM(E6:E31) -> 112927.78 | H32: =SUM(H6:H31) -> 222192.92 | I32: =SUM(I6:I31) -> 157791.23 | J32: =SUM(J6:J31) -> 1701684.9 | K32: =IF(J32=0,0,I32/J32*1000) -> 92.726465
D35: ОСНОВНЫЕ ИНПУТЫ — единые ценовые и эмиссионные допущения (связаны с листом «Расчёты»)
D36: Цена угля | E36: 15 | F36: $/т | G36: Внутренний рынок КЗ
D37: Цена газа | E37: 250 | F37: $/тыс.м³ | G37: Внутренний тариф КЗ (несубсид.)
D38: Цена ЭЭ (ВИЭ, опт.) | E38: 50 | F38: $/МВтч | G38: KOREM, аукционы ВИЭ
D39: EF угля (электрогенерация) | E39: 1 | F39: тCO₂/МВтч
D40: EF газа (электрогенерация) | E40: 0.45 | F40: тCO₂/МВтч
D41: EF угольной котельной/ТЭЦ | E41: 0.55 | F41: тCO₂/Гкал | G41: по теплу
D42: Содержание C в угле | E42: 0.4 | F42: доля | G42: Экибастуз / IPCC default
D44: КЛЮЧЕВЫЕ УДЕЛЬНЫЕ CAPEX (по технологиям)
...

Sheet Выбросы
A1: Выбросы парниковых газов Республики Казахстан по секторам МГЭИК
A2: Источник: Первый двухлетний доклад о прозрачности (BTR1), РКИК ООН, ноябрь 2024
A3: Год инвентаризации: 2022. GWP: AR5. Методология: Руководящие принципы МГЭИК 2006
A5: Код МГЭИК | B5: Сектор / подкатегория | C5: Mt CO₂eq | D5: % от общих | E5: 1990 Mt | F5: Δ 1990/2022 | G5: Источник / примечание
A6: 1 | B6: ЭНЕРГЕТИКА | C6: 281.9 | D6: 0.80819954 | E6: 322 | F6: -0.12453416 | G6: BTR1, Таблица 1 | J6: 2
A7: 1.A | B7: Сжигание топлива | C7: 238.2 | D7: 0.68291284 | E7: 262 | F7: -0.090839695 | G7: ≈84.5% от сектора 1, пропорция NIR 2023 | J7: 4
A8: 1.A.1 | B8: Энергетические отрасли (ТЭЦ, ГРЭС, котельные) | C8: 135.3 | D8: 0.38790138 | E8: 166 | F8: -0.18493976 | G8: ≈48% от сектора 1. Электро- и теплогенерация | J8: 2
A9: 1.A.2 | B9: Обрабатывающая промышленность и строительство | C9: 26.2 | D9: 0.075114679 | E9: 32.7 | F9: -0.19877676 | G9: ≈9.3% от сектора 1. Металлургия, НПЗ, химия
A10: 1.A.3 | B10: Транспорт | C10: 27.1 | D10: 0.077694954 | E10: 28.4 | F10: -0.045774648 | G10: ≈9.6% от сектора 1. Автомобильный, ж/д, авиация
A11: 1.A.4 | B11: Другие секторы (ЖКХ, коммерческий, с/х) | C11: 46.5 | D11: 0.13331422 | E11: 32.6 | F11: 0.42638037 | G11: ≈16.5% от сектора 1. Отопление зданий
A12: 1.A.5 | B12: Прочее | C12: 3.1 | D12: 0.0088876147 | E12: 2.3 | F12: 0.34782609 | G12: Военная деятельность и пр.
A13: 1.B | B13: Фугитивные выбросы | C13: 43.7 | D13: 0.1252867 | E13: 60 | F13: -0.27166667 | G13: ≈15.5% от сектора 1. Нефтегаз + угольные шахты
A14: 1.B.1 | B14: Твёрдое топливо (уголь) | C14: 9.5 | D14: 0.027236239 | E14: 22 | F14: -0.56818182 | G14: Дегазация угольных шахт, Караганда
A15: 1.B.2 | B15: Нефть и газ | C15: 34.2 | D15: 0.098050459 | E15: 38 | F15: -0.1 | G15: Факельное сжигание, утечки, вентиляция
A16: 2 | B16: ПРОМЫШЛЕННЫЕ ПРОЦЕССЫ И ИСПОЛЬЗОВАНИЕ ПРОДУКЦИИ (IPPU) | C16: 27 | D16: 0.077408257 | E16: 22.7 | F16: 0.18942731 | G16: BTR1, Таблица 1
A17: 2.A | B17: Минеральная промышленность | C17: 8.6 | D17: 0.024655963 | E17: 5.4 | F17: 0.59259259 | G17: ≈32% от IPPU. Цемент, известь, стекло
A18: 2.B | B18: Химическая промышленность | C18: 1.1 | D18: 0.0031536697 | E18: 1.5 | F18: -0.26666667 | G18: ≈4% от IPPU
A19: 2.C | B19: Металлургия | C19: 14.9 | D19: 0.04271789 | E19: 13.5 | F19: 0.1037037 | G19: ≈55% от IPPU. Чугун, сталь, ферросплавы, алюминий
A20: 2.D-F | B20: Прочее IPPU (ГФУ, ПФУ, SF₆, растворители) | C20: 2.4 | D20: 0.0068807339 | E20: 2.3 | F20: 0.043478261 | G20: F-газы: 2.7 Mt CO₂eq (BTR1 текст)
... A25: 3.D | B25: Сельскохозяйственные почвы | C25: 11.6 | D25: 0.033256881 | E25: 10.9 | F25: 0.064220183 | G25: ≈35%. N₂O от удобрений и растит. остатков
A26: 4 | B26: ЗЕМЛЕПОЛЬЗОВАНИЕ (LULUCF) | C26: 4.13 | E26: -4.79 | F26: н/п | G26: BTR1, Таблица 1. Нетто-источник с ~2000 г.
A27: 5 | B27: ОТХОДЫ | C27: 6.9 | D27: 0.01978211 | E27: 4 | F27: 0.725 | G27: BTR1, Таблица 1
A28: 5.A | B28: Захоронение твёрдых отходов | C28: 3.6 | D28: 0.010321101 | E28: 2 | F28: 0.8 | G28: ≈52% от сектора. Полигоны ТБО
A29: 5.D | B29: Очистка сточных вод | C29: 3.2 | D29: 0.0091743119 | E29: 1.9 | F29: 0.68421053 | G29: ≈47%. CH₄ от анаэробных процессов
A30: 5.C | B30: Сжигание отходов | C30: 0.1 | D30: 0.00028669725 | E30: 0.1 | F30: 0 | G30: ≈1%
B32: ИТОГО БЕЗ LULUCF | C32: 348.8 | D32: 1 | E32: 390.5 | F32: -0.10678617 | G32: BTR1, Таблица 1
B33: ИТОГО С LULUCF (нетто) | C33: 353 | E33: 385.7 | F33: -0.084780918 | G33: BTR1, Таблица 1
A35: Примечания:
A36: 1. Данные по основным секторам (1, 2, 3, 4, 5) — официальные из BTR1 Казахстана (РКИК ООН, ноябрь 2024), Таблица 1.
A37: 2. Данные по подкатегориям (1.A.1, 1.A.2 и т.д.) — оценочные, на основе пропорций из GHG Profile и NIR 2023.
A38: 3. Для обновления подкатегорий до официальных данных используйте CRT таблицы (Common Reporting Tables), поданные в декабрь 2024.
A39: 4. GWP: AR5 (CO₂=1, CH₄=28, N₂O=265). Методология: IPCC 2006 Guidelines.
A40: 5. NDC Казахстана: безусловная цель −15% к 2030 от 1990 (≤332 Mt), условная −25% (≤293 Mt).
A41: 6. В 2022 году выбросы без LULUCF составили 348.8 Mt, что на 10.7% ниже 1990 и на 7.8% выше 2021 (постковидное восстановление).
A43: Источники:
A44: BTR1: https://unfccc.int/sites/default/files/resource/BTR1%20Kazakhstan_en.pdf
A45: Carbon Neutrality Strategy 2060: https://unfccc.int/sites/default/files/resource/Carbon_Neutrlaity_Strategy_Kazakhstan_Eng_Oct2024.pdf
A46: UNFCCC Data Interface: https://di.unfccc.int/detailed_data_by_party

Sheet Расчёты
B1: РАСЧЁТЫ МЕРОПРИЯТИЙ
A2: [1.A.1-1] Повышение КПД угольных ТЭЦ (модернизация турбин и котлов) | G2: 1
B3: ПРЕДПОСЫЛКИ И ИСХОДНЫЕ ДАННЫЕ
B4: Выбросы сектора 1.A.1 | C4: =Выбросы!C8 -> 135.3 | E4: Mt CO₂eq/год | F4: UNFCCC NIR 2023
B5: Доля мероприятия | C5: =C6 -> 0.02
B6: Повышение КПД (абс.) | C6: 0.02 | E6: п.п. | F6: 2%, типичная модернизация
B7: Уд. CAPEX модернизации | C7: =MACC!$E$45 -> 500 | E7: $/кВт | F7: Оборудование
B8: Средний КИУМ | C8: 0.55 | F8: Статистика KEGOC
B9: Цена угля | C9: =MACC!$E$36 -> 15 | E9: $/т | F9: Внутренний рынок КЗ
B10: Содержание C в угле | C10: =MACC!$E$42 -> 0.4 | F10: Экибастуз
B11: Срок службы | C11: 20 | E11: лет
B12: РАСЧЁТ СНИЖЕНИЯ ВЫБРОСОВ
B13: Снижение выбросов | C13: =C4*C5*1000 -> 2706 | E13: kt CO₂eq/год
B14: Замещаемая мощность | C14: 15000 | E14: МВт | F14: оценка действующей генерации
B15: CAPEX (mUSD)
B16: Модернизация турбин и котлов | C16: =C14*C7/1000 -> 7500
B17: Проектные и пусконаладочные работы | C17: =C16*0.3 -> 2250 | F17: 30% от оборудования
B18: ИТОГО CAPEX | C18: =SUM(C16:C17) -> 9750
B19: OPEX (mUSD/год, инкрементально)
B20: ТОиР | C20: =C18*E20 -> 97.5 | E20: 0.01 | F20: 1% от CAPEX
B21: Экономия топлива | C21: =E21*C9 -> -27.675 | E21: =-C13*1000/(C10*44/12)/10^6 -> -1.845 | F21: млн т угля
B22: ИТОГО OPEX | C22: =SUM(C20:C21) -> 69.825
B23: КЛЮЧЕВЫЕ ВЫХОДЫ → таблица MACC
B24: CAPEX | C24: =C18 -> 9750 | E24: mUSD
B25: OPEX | C25: =C22 -> 69.825 | E25: mUSD/год
B26: Срок службы | C26: =C11 -> 20 | E26: лет
B27: Снижение выбросов | C27: =C13 -> 2706 | E27: kt CO₂eq/год
A29: [1.A.1-2] Перевод угольных ТЭЦ и котельных на природный газ | G29: 1
B30: ПРЕДПОСЫЛКИ И ИСХОДНЫЕ ДАННЫЕ
B31: Выбросы сектора 1.A.1 | C31: =Выбросы!C8 -> 135.3 | E31: Mt CO₂eq/год | F31: UNFCCC NIR 2023
B32: Доля мероприятия | C32: =C42/1000/C31 -> 0.08902439 | F32: Лист «Мероприятия»
B33: Уд. CAPEX перевода | C33: =MACC!$E$46 -> 1500 | E33: $/кВт | F33: IEA, gas turbine + pipeline
B34: Доля затрат: газопровод и подключение | C34: 0.4 | F34: Экспертная оценка
B35: Цена газа | C35: =MACC!$E$37 -> 250 | E35: $/тыс.м³ | F35: Внутренний тариф КЗ
B36: Цена угля | C36: =MACC!$E$36 -> 15 | E36: $/т | F36: Внутренний рынок
B37: EF угля | C37: =MACC!$E$39 -> 1 | E37: тCO2/МВтч
B38: EF газа | C38: =MACC!$E$40 -> 0.45 | E38: тCO2/МВтч
B39: КИУМ | C39: 0.5
B40: Срок службы | C40: 20 | E40: лет
B41: РАСЧЁТ СНИЖЕНИЯ ВЫБРОСОВ
...
